Environment:


Request Method: GET
Request URL: https://805e877f-4910-41df-b235-f52b38e8e842-00-1wslzvvsdtatb.riker.replit.dev/users/profile/10/

Django Version: 5.2.3
Python Version: 3.12.7
Installed Applications:
['django.contrib.admin',
 'django.contrib.auth',
 'django.contrib.contenttypes',
 'django.contrib.sessions',
 'django.contrib.messages',
 'django.contrib.staticfiles',
 'django.contrib.humanize',
 'rest_framework',
 'django_filters',
 'channels',
 'users.apps.UsersConfig',
 'listings.apps.ListingsConfig',
 'chat.apps.ChatConfig',
 'notifications.apps.NotificationsConfig',
 'moderation.apps.ModerationConfig',
 'subscriptions.apps.SubscriptionsConfig',
 'django_extensions']
Installed Middleware:
['django.middleware.security.SecurityMiddleware',
 'django.contrib.sessions.middleware.SessionMiddleware',
 'django.middleware.common.CommonMiddleware',
 'django.middleware.csrf.CsrfViewMiddleware',
 'django.contrib.auth.middleware.AuthenticationMiddleware',
 'django.contrib.messages.middleware.MessageMiddleware',
 'django.middleware.clickjacking.XFrameOptionsMiddleware']



Traceback (most recent call last):
  File "/home/runner/workspace/.pythonlibs/lib/python3.12/site-packages/django/core/handlers/exception.py", line 55, in inner
    response = get_response(request)
               ^^^^^^^^^^^^^^^^^^^^^
  File "/home/runner/workspace/.pythonlibs/lib/python3.12/site-packages/django/core/handlers/base.py", line 197, in _get_response
    response = wrapped_callback(request, *callback_args, **callback_kwargs)
               ^^^^^^^^^^^^^^^^^^^^^^^^^^^^^^^^^^^^^^^^^^^^^^^^^^^^^^^^^^^^
  File "/home/runner/workspace/users/views.py", line 150, in public_profile_view
    existing_review = reviews_received.filter(reviewer=request.user).exists()
                      ^^^^^^^^^^^^^^^^^^^^^^^^^^^^^^^^^^^^^^^^^^^^^^
  File "/home/runner/workspace/.pythonlibs/lib/python3.12/site-packages/django/db/models/query.py", line 1493, in filter
    return self._filter_or_exclude(False, args, kwargs)
           ^^^^^^^^^^^^^^^^^^^^^^^^^^^^^^^^^^^^^^^^^^^^
  File "/home/runner/workspace/.pythonlibs/lib/python3.12/site-packages/django/db/models/query.py", line 1505, in _filter_or_exclude
    raise TypeError("Cannot filter a query once a slice has been taken.")
    ^^^^^^^^^^^^^^^^^^^^^^^^^^^^^^^^^^^^^^^^^^^^^^^^^^^^^^^^^^^^^^^^^^^^^

Exception Type: TypeError at /users/profile/10/
Exception Value: Cannot filter a query once a slice has been taken.
